Workbook

Sheet AoS Advanced Simulator
A1: Age of Sigmar Advanced Combat Simulator
A3: Number of Attacks (max 30) | B3: 12 | D3: Average Damage | E3: =AVERAGE(B120:B1119) -> 12.48
A4: Hit roll needed | B4: 4 | D4: Min Damage | E4: =MIN(B120:B1119) -> 0
A5: Wound roll needed | B5: 2 | D5: Max Damage | E5: =MAX(B120:B1119) -> 27
A6: Enemy Save | B6: 4 | D6: Kill Probability | E6: =COUNTIF(B120:B1119,">="&B16)/1000 -> 0.073
A7: Rend | B7: -2
A8: Ward Save (0 if none) | B8: 0
A9: Damage Type (1=Fixed,2=D3,3=D6) | B9: 1
A10: Fixed Damage | B10: 3
A11: Mortal Wound on Hit 6 (0=no,1=yes) | B11: 0
A12: Reroll Hits (0=no,1=yes) | B12: 0
A13: Reroll Wounds (0=no,1=yes) | B13: 0
A14: All-out Attack (0=no,1=yes) | B14: 0
A15: All-out Defense (0=no,1=yes) | B15: 0
A16: Target Wounds (kill probability) | B16: 21
H29: Damage | I29: Frequency
H30: 0 | I30: =COUNTIF(B120:B1119,0) -> 3
H31: 1 | I31: =COUNTIF(B120:B1119,1) -> 0
H32: 2 | I32: =COUNTIF(B120:B1119,2) -> 0
H33: 3 | I33: =COUNTIF(B120:B1119,3) -> 39
H34: 4 | I34: =COUNTIF(B120:B1119,4) -> 0
H35: 5 | I35: =COUNTIF(B120:B1119,5) -> 0
H36: 6 | I36: =COUNTIF(B120:B1119,6) -> 106
H37: 7 | I37: =COUNTIF(B120:B1119,7) -> 0
H38: 8 | I38: =COUNTIF(B120:B1119,8) -> 0
H39: 9 | I39: =COUNTIF(B120:B1119,9) -> 201
H40: 10 | I40: =COUNTIF(B120:B1119,10) -> 0
H41: 11 | I41: =COUNTIF(B120:B1119,11) -> 0
H42: 12 | I42: =COUNTIF(B120:B1119,12) -> 244
H43: 13 | I43: =COUNTIF(B120:B1119,13) -> 0
H44: 14 | I44: =COUNTIF(B120:B1119,14) -> 0
H45: 15 | I45: =COUNTIF(B120:B1119,15) -> 202
H46: 16 | I46: =COUNTIF(B120:B1119,16) -> 0
H47: 17 | I47: =COUNTIF(B120:B1119,17) -> 0
H48: 18 | I48: =COUNTIF(B120:B1119,18) -> 132
H49: 19 | I49: =COUNTIF(B120:B1119,19) -> 0
H50: 20 | I50: =COUNTIF(B120:B1119,20) -> 0
H51: 21 | I51: =COUNTIF(B120:B1119,21) -> 59
H52: 22 | I52: =COUNTIF(B120:B1119,22) -> 0
H53: 23 | I53: =COUNTIF(B120:B1119,23) -> 0
...

Sheet AoS Advanced Simulator TEST
A1: Age of Sigmar Advanced Combat Simulator
A3: UNITA' | B3: 6 Rockgut
A4: Number of Attacks (max 30) | B4: =LOOKUP($B$3,Tabella1[[#Headers],[3 rockgut]:[Knight Azyros]], Foglio2!B2:E2) -> 12 | D4: Average Damage | E4: =AVERAGE(B121:B1120) -> 9.942
A5: Hit roll needed | B5: =LOOKUP($B$3,Tabella1[[#Headers],[3 rockgut]:[Knight Azyros]], Foglio2!B3:E3) -> 4 | D5: Min Damage | E5: =MIN(B121:B1120) -> 0
A6: Wound roll needed | B6: =LOOKUP($B$3,Tabella1[[#Headers],[3 rockgut]:[Knight Azyros]], Foglio2!B4:E4) -> 2 | D6: Max Damage | E6: =MAX(B121:B1120) -> 27
A7: Enemy Save | B7: 3 | D7: Kill Probability | E7: =COUNTIF(B121:B1120,">="&B17)/1000 -> 0.43
A8: Rend | B8: =LOOKUP($B$3,Tabella1[[#Headers],[3 rockgut]:[Knight Azyros]], Foglio2!B6:E6) -> -2
A9: Ward Save (0 if none) | B9: 0
A10: Damage Type (1=Fixed,2=D3,3=D6) | B10: =LOOKUP($B$3,Tabella1[[#Headers],[3 rockgut]:[Knight Azyros]], Foglio2!B8:E8) -> 1
A11: Fixed Damage | B11: =LOOKUP($B$3,Tabella1[[#Headers],[3 rockgut]:[Knight Azyros]], Foglio2!B9:E9) -> 3
A12: Mortal Wound on Hit 6 (0=no,1=yes) | B12: =LOOKUP($B$3,Tabella1[[#Headers],[3 rockgut]:[Knight Azyros]], Foglio2!B10:E10) -> 0
A13: Reroll Hits (0=no,1=yes) | B13: 0
A14: Reroll Wounds (0=no,1=yes) | B14: 0
A15: All-out Attack (0=no,1=yes) | B15: 0
A16: All-out Defense (0=no,1=yes) | B16: 0
A17: Target Wounds (kill probability) | B17: 12
H30: Damage | I30: Frequency
H31: 0 | I31: =COUNTIF(B121:B1120,0) -> 22
H32: 1 | I32: =COUNTIF(B121:B1120,1) -> 0
H33: 2 | I33: =COUNTIF(B121:B1120,2) -> 0
H34: 3 | I34: =COUNTIF(B121:B1120,3) -> 93
H35: 4 | I35: =COUNTIF(B121:B1120,4) -> 0
H36: 5 | I36: =COUNTIF(B121:B1120,5) -> 0
H37: 6 | I37: =COUNTIF(B121:B1120,6) -> 221
H38: 7 | I38: =COUNTIF(B121:B1120,7) -> 0
H39: 8 | I39: =COUNTIF(B121:B1120,8) -> 0
H40: 9 | I40: =COUNTIF(B121:B1120,9) -> 234
H41: 10 | I41: =COUNTIF(B121:B1120,10) -> 0
H42: 11 | I42: =COUNTIF(B121:B1120,11) -> 0
H43: 12 | I43: =COUNTIF(B121:B1120,12) -> 192
H44: 13 | I44: =COUNTIF(B121:B1120,13) -> 0
H45: 14 | I45: =COUNTIF(B121:B1120,14) -> 0
H46: 15 | I46: =COUNTIF(B121:B1120,15) -> 149
H47: 16 | I47: =COUNTIF(B121:B1120,16) -> 0
H48: 17 | I48: =COUNTIF(B121:B1120,17) -> 0
H49: 18 | I49: =COUNTIF(B121:B1120,18) -> 63
H50: 19 | I50: =COUNTIF(B121:B1120,19) -> 0
H51: 20 | I51: =COUNTIF(B121:B1120,20) -> 0
H52: 21 | I52: =COUNTIF(B121:B1120,21) -> 23
H53: 22 | I53: =COUNTIF(B121:B1120,22) -> 0
...

Sheet Foglio2
A1: Colonna1 | B1: 3 rockgut | C1: 6 Rockgut | D1: Gardus | E1: Knight Azyros
A2: Number of Attacks (max 30) | B2: 6 | C2: 12 | D2: 5 | E2: 5
A3: Hit roll needed | B3: 4 | C3: 4 | D3: 3 | E3: 3
A4: Wound roll needed | B4: 2 | C4: 2 | D4: 3 | E4: 3
A5: Enemy Save
A6: Rend | B6: -2 | C6: -2 | D6: -1 | E6: -1
A7: Ward Save
A8: Damage Type (1=Fixed,2=D3,3=D6) | B8: 1 | C8: 1 | D8: 1 | E8: 1
A9: Fixed Damage | B9: 3 | C9: 3 | D9: 2 | E9: 2
A10: Mortal Wound on Hit 6 (0=no,1=yes) | B10: 0 | C10: 0 | D10: 0 | E10: 0
A11: Reroll Hits (0=no,1=yes) | B11: 0 | C11: 0 | D11: 0 | E11: 0
A12: Reroll Wounds (0=no,1=yes) | B12: 0 | C12: 0 | D12: 0 | E12: 0
A13: All-out Attack (0=no,1=yes)
A14: All-out Defense (0=no,1=yes)
A15: Target Wounds (kill probability)
